Workbook

Sheet RESULTADO
D1: REALIZADO
A2: DISCRIMINAÇÃO | D2: VALOR R$
A3: 1.Faturamento YOU
A4: Reembolsos stone
A5: A&B&E | D5: =SUM('Faturamento L1 e L2'!J27:K27,'Faturamento L1 e L2'!M27,'Faturamento RTC'!J17:K17,'Faturamento RTC'!M17) -> 0
A7: 2.Faturamento Experience | D7: =SUM(D8:D9) -> 0
A8: L1 + L2 | D8: =SUM('Faturamento L1 e L2'!I27,'Faturamento L1 e L2'!L27) -> 0
A9: RTC | D9: =SUM('Faturamento RTC'!I17,'Faturamento RTC'!L17) -> 0
A10: Total
A12: 4. Custos Loja You | D12: VALOR R$
A13: Total | D13: ='GASTOS POR ESPAÇO'!B124 -> 116271.65
A14: Resultado You BAR | D14: =D3-D13 -> -116271.65
A17: 8. Espaços 178 | B17: Receitas | C17: Despesas | D17: Resultado
A18: L1 + L2 | B18: =D8 -> 0 | C18: =SUM('GASTOS POR ESPAÇO'!E124,'GASTOS POR ESPAÇO'!H124) -> 40406.124 | D18: =B18-C18 -> -40406.124
A19: RTC | B19: =D9 -> 0 | C19: ='GASTOS POR ESPAÇO'!K124 -> 7923.2951 | D19: =B19-C19 -> -7923.2951
A21: Resultado 178 | D21: =SUM(D18:D19) -> -48329.419
C22: Yield (3mi) | D22: =D21/3000000 -> -0.016109806
B28: 62311
B29: 29284
B31: =SUM(B28:B30) -> 91595 | C31: =SUM(C18:C19,D13) -> 164601.07
B32: 104000

Sheet Faturamento L1 e L2

Sheet Faturamento RTC
A1: Simulação | B1: Reserva | C1: Cliente | D1: Data Aceite | E1: Data Check-in | G1: Valor sim. | H1: Locação espaço | I1: Alim./bebidas | J1: Equipe apoio | K1: Loc. equip. | L1: Entretenimento | M1: Total | N1: Anúncio | O1: Tem Check-out?
A2: [7539] | B2: 4981 | C2: Elaine Maria Silva de Souza | D2: 46066 | E2: 46082 | F2: =G2-SUM(H2:L2) -> 900 | G2: 3000 | H2: 2100 | I2: 0 | J2: 0 | K2: 0 | L2: 0 | M2: 2100 | N2: 0 | O2: Sim
A3: [7213] | B3: 4925 | C3: Ana Beneck | D3: 46050 | E3: 46088 | F3: =G3-SUM(H3:L3) -> 1111.5 | G3: 3736.5 | H3: =G3-1111.5 -> 2625 | I3: 0 | J3: 0 | K3: 0 | L3: 0 | M3: 0 | N3: 146 | O3: SEM DESOCUP.
A4: [7601] | B4: 4994 | C4: Sharim Amar Borrione Arab | D4: 46073 | E4: 46089 | F4: =G4-SUM(H4:L4) -> 900 | G4: 3000 | H4: 2100 | I4: 0 | J4: 0 | K4: 0 | L4: 0 | M4: 2100 | N4: 64 | O4: Sim
A5: [7563] | B5: 4988 | C5: Globopack Embalagens | D5: 46071 | E5: 46091 | F5: =G5-SUM(H5:L5) -> 900 | G5: 3000 | H5: 2100 | I5: 0 | J5: 0 | K5: 0 | L5: 0 | M5: 2100 | N5: 121 | O5: Sim
A6: [7510] | B6: 4972 | C6: Juliana Maria Andrade de Carvalho | D6: 46065 | E6: 46092 | F6: =G6-SUM(H6:L6) -> 900 | G6: 3000 | H6: 2100 | I6: 0 | J6: 0 | K6: 0 | L6: 0 | M6: 2100 | N6: 0 | O6: Sim
A7: [7804] | B7: 5019 | C7: Maria Eduarda penkal | D7: 46091 | E7: 46093 | F7: =G7-SUM(H7:L7) -> 0 | G7: 200 | H7: 0 | I7: 0 | J7: 0 | K7: 200 | L7: 0 | M7: 200 | N7: 0 | O7: Sim
A8: [7731] | B8: 5010 | C8: Fabiola Gonçalves dos Santos | D8: 46084 | E8: 46095 | F8: =G8-SUM(H8:L8) -> 0 | G8: 165 | H8: 165 | I8: 0 | J8: 0 | K8: 0 | L8: 0 | M8: 165 | N8: 175 | O8: SEM DESOCUP.
A9: [6976] | B9: A confirmar | C9: Fabiola Gonçalves dos Santos | D9: 46034 | E9: 46095 | F9: =G9-SUM(H9:L9) -> 900 | G9: 900 | H9: 0 | I9: 0 | J9: 0 | K9: 0 | L9: 0 | M9: 0 | N9: 175 | O9: SEM DESOCUP.
A10: [6975] | B10: 4890 | C10: Fabiola Gonçalves dos Santos | D10: 46034 | E10: 46095 | F10: =G10-SUM(H10:L10) -> 157.5 | G10: 2782.5 | H10: 2625 | I10: 0 | J10: 0 | K10: 0 | L10: 0 | M10: 2625 | N10: 175 | O10: Sim
A11: [7900] | B11: 5028 | C11: Emanuel Ribas Santos | D11: 46098 | E11: 46098 | F11: =G11-SUM(H11:L11) -> 0 | G11: 278.1 | H11: 0 | I11: 278.1 | J11: 0 | K11: 0 | L11: 0 | M11: 278.1 | N11: 0 | O11: SEM DESOCUP.
A12: [6768] | B12: 4859 | C12: Cirde Eufrázio da Silva Filho | D12: 46010 | E12: 46102 | F12: =G12-SUM(H12:L12) -> 900 | G12: 3400 | H12: 2500 | I12: 0 | J12: 0 | K12: 0 | L12: 0 | M12: 2500 | N12: 0 | O12: Sim
A13: [7461] | B13: 4962 | C13: Thays cândido da silva | D13: 46063 | E13: 46109 | F13: =G13-SUM(H13:L13) -> 900 | G13: 3525 | H13: 2625 | I13: 0 | J13: 0 | K13: 0 | L13: 0 | M13: 2625 | N13: 0 | O13: Sim
H15: =SUM(H2:H13) -> 18940 | I15: =SUM(I2:I13) -> 278.1 | J15: =SUM(J2:J13) -> 0 | K15: =SUM(K2:K13) -> 200 | L15: =SUM(L2:L13) -> 0
E18: 178 | F18: =SUM(H15,K15) -> 19140

Sheet GASTOS POR ESPAÇO
A1: YOU | D1: L1 | G1: L2 | J1: RTC
A2: FORNECEDOR/GRUPO | B2: REALIZADO | D2: FORNECEDOR/GRUPO | E2: REALIZADO | G2: FORNECEDOR/GRUPO | H2: REALIZADO | J2: FORNECEDOR/GRUPO | K2: REALIZADO
A3: BAR | D3: BAR | G3: BAR | J3: BAR
A4: INSUMO BAR | B4: =SUMIFS('GASTOS DETALHADOS'!$C:$C,'GASTOS DETALHADOS'!$E:$E,A$1,'GASTOS DETALHADOS'!$F:$F,A4) -> 11786.73 | D4: INSUMO BAR | E4: =SUMIFS('GASTOS DETALHADOS'!$C:$C,'GASTOS DETALHADOS'!$E:$E,D$1,'GASTOS DETALHADOS'!$F:$F,D4) -> 0 | G4: INSUMO BAR | H4: =SUMIFS('GASTOS DETALHADOS'!$C:$C,'GASTOS DETALHADOS'!$E:$E,G$1,'GASTOS DETALHADOS'!$F:$F,G4) -> 0 | J4: INSUMO BAR | K4: =SUMIFS('GASTOS DETALHADOS'!$C:$C,'GASTOS DETALHADOS'!$E:$E,J$1,'GASTOS DETALHADOS'!$F:$F,J4) -> 0
A5: Utensílios | D5: Utensílios | G5: Utensílios | J5: Utensílios
B6: =SUM(B4:B5) -> 11786.73 | E6: =SUM(E4:E5) -> 0 | H6: =SUM(H4:H5) -> 0 | K6: =SUM(K4:K5) -> 0
A7: COZINHA | D7: COZINHA | G7: COZINHA | J7: COZINHA
A8: INSUMO COZ | B8: =SUMIFS('GASTOS DETALHADOS'!$C:$C,'GASTOS DETALHADOS'!$E:$E,A$1,'GASTOS DETALHADOS'!$F:$F,A8) -> 32088.31 | D8: INSUMO COZ | E8: =SUMIFS('GASTOS DETALHADOS'!$C:$C,'GASTOS DETALHADOS'!$E:$E,D$1,'GASTOS DETALHADOS'!$F:$F,D8) -> 0 | G8: INSUMO COZ | H8: =SUMIFS('GASTOS DETALHADOS'!$C:$C,'GASTOS DETALHADOS'!$E:$E,G$1,'GASTOS DETALHADOS'!$F:$F,G8) -> 0 | J8: INSUMO COZ | K8: =SUMIFS('GASTOS DETALHADOS'!$C:$C,'GASTOS DETALHADOS'!$E:$E,J$1,'GASTOS DETALHADOS'!$F:$F,J8) -> 0
A9: Utensílios | D9: Utensílios | G9: Utensílios | J9: Utensílios
B10: =SUM(B8:B9) -> 32088.31 | E10: =SUM(E8:E9) -> 0 | H10: =SUM(H8:H9) -> 0 | K10: =SUM(K8:K9) -> 0
A11: SALÃO | D11: SALÃO | G11: SALÃO | J11: SALÃO
A12: INSUMO SALÃO | B12: =SUMIFS('GASTOS DETALHADOS'!$C:$C,'GASTOS DETALHADOS'!$E:$E,A$1,'GASTOS DETALHADOS'!$F:$F,A12) -> 265.7 | D12: INSUMO SALÃO | E12: =SUMIFS('GASTOS DETALHADOS'!$C:$C,'GASTOS DETALHADOS'!$E:$E,D$1,'GASTOS DETALHADOS'!$F:$F,D12) -> 355.89 | G12: INSUMO SALÃO | H12: =SUMIFS('GASTOS DETALHADOS'!$C:$C,'GASTOS DETALHADOS'!$E:$E,G$1,'GASTOS DETALHADOS'!$F:$F,G12) -> 0 | J12: INSUMO SALÃO | K12: =SUMIFS('GASTOS DETALHADOS'!$C:$C,'GASTOS DETALHADOS'!$E:$E,J$1,'GASTOS DETALHADOS'!$F:$F,J12) -> 0
A13: ALUGUEL ITENS DIVERSOS | B13: =SUMIFS('GASTOS DETALHADOS'!$C:$C,'GASTOS DETALHADOS'!$E:$E,A$1,'GASTOS DETALHADOS'!$F:$F,A13) -> 3369 | D13: ALUGUEL ITENS DIVERSOS | E13: =SUMIFS('GASTOS DETALHADOS'!$C:$C,'GASTOS DETALHADOS'!$E:$E,D$1,'GASTOS DETALHADOS'!$F:$F,D13) -> 3210 | G13: ALUGUEL ITENS DIVERSOS | H13: =SUMIFS('GASTOS DETALHADOS'!$C:$C,'GASTOS DETALHADOS'!$E:$E,G$1,'GASTOS DETALHADOS'!$F:$F,G13) -> 0 | J13: ALUGUEL ITENS DIVERSOS | K13: =SUMIFS('GASTOS DETALHADOS'!$C:$C,'GASTOS DETALHADOS'!$E:$E,J$1,'GASTOS DETALHADOS'!$F:$F,J13) -> 0
A14: Utensílios | B14: =SUMIFS('GASTOS DETALHADOS'!$C:$C,'GASTOS DETALHADOS'!$E:$E,A$1,'GASTOS DETALHADOS'!$F:$F,A14) -> 0 | D14: Utensílios | E14: =SUMIFS('GASTOS DETALHADOS'!$C:$C,'GASTOS DETALHADOS'!$E:$E,D$1,'GASTOS DETALHADOS'!$F:$F,D14) -> 0 | G14: Utensílios | H14: =SUMIFS('GASTOS DETALHADOS'!$C:$C,'GASTOS DETALHADOS'!$E:$E,G$1,'GASTOS DETALHADOS'!$F:$F,G14) -> 0 | J14: Utensílios | K14: =SUMIFS('GASTOS DETALHADOS'!$C:$C,'GASTOS DETALHADOS'!$E:$E,J$1,'GASTOS DETALHADOS'!$F:$F,J14) -> 0
B15: =SUM(B12:B14) -> 3634.7 | E15: =SUM(E12:E14) -> 3565.89 | H15: =SUM(H12:H14) -> 0 | K15: =SUM(K12:K14) -> 0
A16: LIMPEZA | D16: LIMPEZA | G16: LIMPEZA | J16: LIMPEZA
A17: INSUMO LIMP | B17: =SUMIFS('GASTOS DETALHADOS'!$C:$C,'GASTOS DETALHADOS'!$E:$E,A$1,'GASTOS DETALHADOS'!$F:$F,A17) -> 19 | D17: INSUMO LIMP | E17: =SUMIFS('GASTOS DETALHADOS'!$C:$C,'GASTOS DETALHADOS'!$E:$E,D$1,'GASTOS DETALHADOS'!$F:$F,D17) -> 514.09333 | G17: INSUMO LIMP | H17: =SUMIFS('GASTOS DETALHADOS'!$C:$C,'GASTOS DETALHADOS'!$E:$E,G$1,'GASTOS DETALHADOS'!$F:$F,G17) -> 514.09333 | J17: INSUMO LIMP | K17: =SUMIFS('GASTOS DETALHADOS'!$C:$C,'GASTOS DETALHADOS'!$E:$E,J$1,'GASTOS DETALHADOS'!$F:$F,J17) -> 514.09333
A18: Utensílios | B18: =SUMIFS('GASTOS DETALHADOS'!$C:$C,'GASTOS DETALHADOS'!$E:$E,A$1,'GASTOS DETALHADOS'!$F:$F,A18) -> 0 | D18: Utensílios | E18: =SUMIFS('GASTOS DETALHADOS'!$C:$C,'GASTOS DETALHADOS'!$E:$E,D$1,'GASTOS DETALHADOS'!$F:$F,D18) -> 0 | G18: Utensílios | H18: =SUMIFS('GASTOS DETALHADOS'!$C:$C,'GASTOS DETALHADOS'!$E:$E,G$1,'GASTOS DETALHADOS'!$F:$F,G18) -> 0 | J18: Utensílios | K18: =SUMIFS('GASTOS DETALHADOS'!$C:$C,'GASTOS DETALHADOS'!$E:$E,J$1,'GASTOS DETALHADOS'!$F:$F,J18) -> 0
B19: =SUM(B17:B18) -> 19 | E19: =SUM(E17:E18) -> 514.09333 | H19: =SUM(H17:H18) -> 514.09333 | K19: =SUM(K17:K18) -> 514.09333
A20: PALCO | D20: PALCO | G20: PALCO | H20: =SUMIFS('GASTOS DETALHADOS'!$C:$C,'GASTOS DETALHADOS'!$E:$E,G$1,'GASTOS DETALHADOS'!$F:$F,G20) -> 0 | J20: PALCO
A21: Insumos | B21: =SUMIFS('GASTOS DETALHADOS'!$C:$C,'GASTOS DETALHADOS'!$E:$E,A$1,'GASTOS DETALHADOS'!$F:$F,A21) -> 0 | D21: Insumos | E21: =SUMIFS('GASTOS DETALHADOS'!$C:$C,'GASTOS DETALHADOS'!$E:$E,D$1,'GASTOS DETALHADOS'!$F:$F,D21) -> 0 | G21: Insumos | H21: =SUMIFS('GASTOS DETALHADOS'!$C:$C,'GASTOS DETALHADOS'!$E:$E,G$1,'GASTOS DETALHADOS'!$F:$F,G21) -> 0 | J21: Insumos | K21: =SUMIFS('GASTOS DETALHADOS'!$C:$C,'GASTOS DETALHADOS'!$E:$E,J$1,'GASTOS DETALHADOS'!$F:$F,J21) -> 0
A22: Utensílios | B22: =SUMIFS('GASTOS DETALHADOS'!$C:$C,'GASTOS DETALHADOS'!$E:$E,A$1,'GASTOS DETALHADOS'!$F:$F,A22) -> 0 | D22: Utensílios | E22: =SUMIFS('GASTOS DETALHADOS'!$C:$C,'GASTOS DETALHADOS'!$E:$E,D$1,'GASTOS DETALHADOS'!$F:$F,D22) -> 0 | G22: Utensílios | H22: =SUMIFS('GASTOS DETALHADOS'!$C:$C,'GASTOS DETALHADOS'!$E:$E,G$1,'GASTOS DETALHADOS'!$F:$F,G22) -> 0 | J22: Utensílios | K22: =SUMIFS('GASTOS DETALHADOS'!$C:$C,'GASTOS DETALHADOS'!$E:$E,J$1,'GASTOS DETALHADOS'!$F:$F,J22) -> 0
B23: =SUM(B21:B22) -> 0 | E23: =SUM(E21:E22) -> 0 | H23: =SUM(H21:H22) -> 0 | K23: =SUM(K21:K22) -> 0
A24: MANUTENÇÃO | D24: MANUTENÇÃO | G24: MANUTENÇÃO | J24: MANUTENÇÃO
A25: REPOSIÇÃO INSUMOS | B25: =SUMIFS('GASTOS DETALHADOS'!$C:$C,'GASTOS DETALHADOS'!$E:$E,A$1,'GASTOS DETALHADOS'!$F:$F,A25) -> 0 | D25: REPOSIÇÃO INSUMOS | E25: =SUMIFS('GASTOS DETALHADOS'!$C:$C,'GASTOS DETALHADOS'!$E:$E,D$1,'GASTOS DETALHADOS'!$F:$F,D25) -> 0 | G25: REPOSIÇÃO INSUMOS | H25: =SUMIFS('GASTOS DETALHADOS'!$C:$C,'GASTOS DETALHADOS'!$E:$E,G$1,'GASTOS DETALHADOS'!$F:$F,G25) -> 0 | J25: REPOSIÇÃO INSUMOS | K25: =SUMIFS('GASTOS DETALHADOS'!$C:$C,'GASTOS DETALHADOS'!$E:$E,J$1,'GASTOS DETALHADOS'!$F:$F,J25) -> 395
A26: MANUTENÇÃO | B26: =SUMIFS('GASTOS DETALHADOS'!$C:$C,'GASTOS DETALHADOS'!$E:$E,A$1,'GASTOS DETALHADOS'!$F:$F,A26) -> 650 | D26: MANUTENÇÃO | E26: =SUMIFS('GASTOS DETALHADOS'!$C:$C,'GASTOS DETALHADOS'!$E:$E,D$1,'GASTOS DETALHADOS'!$F:$F,D26) -> 515.3 | G26: MANUTENÇÃO | H26: =SUMIFS('GASTOS DETALHADOS'!$C:$C,'GASTOS DETALHADOS'!$E:$E,G$1,'GASTOS DETALHADOS'!$F:$F,G26) -> 0 | J26: MANUTENÇÃO | K26: =SUMIFS('GASTOS DETALHADOS'!$C:$C,'GASTOS DETALHADOS'!$E:$E,J$1,'GASTOS DETALHADOS'!$F:$F,J26) -> 0
B27: =SUM(B25:B26) -> 650 | E27: =SUM(E25:E26) -> 515.3 | H27: =SUM(H25:H26) -> 0 | K27: =SUM(K25:K26) -> 395
A28: DESPESAS FIXAS | D28: DESPESAS FIXAS | G28: DESPESAS FIXAS | J28: DESPESAS FIXAS
A29: PROLÁBORE | B29: 6546.3 | D29: ENERGIA | E29: 1500 | G29: ENERGIA | H29: 1000 | J29: ENERGIA | K29: 800
A30: ENERGIA | B30: 1500 | D30: IPTU | E30: 278 | G30: IPTU | H30: 278 | J30: IPTU | K30: 164
A31: CUSTOS BÁSICOS | B31: =SUMIFS('GASTOS DETALHADOS'!$C:$C,'GASTOS DETALHADOS'!$E:$E,A$1,'GASTOS DETALHADOS'!$F:$F,A31) -> 175.26 | D31: CUSTOS BÁSICOS | E31: =SUMIFS('GASTOS DETALHADOS'!$C:$C,'GASTOS DETALHADOS'!$E:$E,D$1,'GASTOS DETALHADOS'!$F:$F,D31) -> 0 | G31: CUSTOS BÁSICOS | H31: =SUMIFS('GASTOS DETALHADOS'!$C:$C,'GASTOS DETALHADOS'!$E:$E,G$1,'GASTOS DETALHADOS'!$F:$F,G31) -> 0 | J31: CUSTOS BÁSICOS | K31: =SUMIFS('GASTOS DETALHADOS'!$C:$C,'GASTOS DETALHADOS'!$E:$E,J$1,'GASTOS DETALHADOS'!$F:$F,J31) -> 0
B32: =SUM(B29:B31) -> 8221.56 | E32: =SUM(E29:E31) -> 1778 | H32: =SUM(H29:H31) -> 1278 | K32: =SUM(K29:K31) -> 964
A33: TRANSPORTE | B33: =SUMIFS('GASTOS DETALHADOS'!$C:$C,'GASTOS DETALHADOS'!$E:$E,A$1,'GASTOS DETALHADOS'!$F:$F,A33) -> 822.3 | D33: TRANSPORTE | E33: =SUMIFS('GASTOS DETALHADOS'!$C:$C,'GASTOS DETALHADOS'!$E:$E,D$1,'GASTOS DETALHADOS'!$F:$F,D33) -> 0 | G33: TRANSPORTE | H33: =SUMIFS('GASTOS DETALHADOS'!$C:$C,'GASTOS DETALHADOS'!$E:$E,G$1,'GASTOS DETALHADOS'!$F:$F,G33) -> 0 | J33: TRANSPORTE | K33: =SUMIFS('GASTOS DETALHADOS'!$C:$C,'GASTOS DETALHADOS'!$E:$E,J$1,'GASTOS DETALHADOS'!$F:$F,J33) -> 20.95
A34: UBER | B34: =SUMIFS('GASTOS DETALHADOS'!$C:$C,'GASTOS DETALHADOS'!$E:$E,A$1,'GASTOS DETALHADOS'!$F:$F,A34) -> 0 | D34: UBER | E34: =SUMIFS('GASTOS DETALHADOS'!$C:$C,'GASTOS DETALHADOS'!$E:$E,D$1,'GASTOS DETALHADOS'!$F:$F,D34) -> 0 | G34: UBER | H34: =SUMIFS('GASTOS DETALHADOS'!$C:$C,'GASTOS DETALHADOS'!$E:$E,G$1,'GASTOS DETALHADOS'!$F:$F,G34) -> 0 | J34: UBER | K34: =SUMIFS('GASTOS DETALHADOS'!$C:$C,'GASTOS DETALHADOS'!$E:$E,J$1,'GASTOS DETALHADOS'!$F:$F,J34) -> 0
A35: VALLET | B35: =SUMIFS('GASTOS DETALHADOS'!$C:$C,'GASTOS DETALHADOS'!$E:$E,A$1,'GASTOS DETALHADOS'!$F:$F,A35) -> 0 | D35: VALLET | E35: =SUMIFS('GASTOS DETALHADOS'!$C:$C,'GASTOS DETALHADOS'!$E:$E,D$1,'GASTOS DETALHADOS'!$F:$F,D35) -> 0 | G35: VALLET | H35: =SUMIFS('GASTOS DETALHADOS'!$C:$C,'GASTOS DETALHADOS'!$E:$E,G$1,'GASTOS DETALHADOS'!$F:$F,G35) -> 0 | J35: VALLET | K35: =SUMIFS('GASTOS DETALHADOS'!$C:$C,'GASTOS DETALHADOS'!$E:$E,J$1,'GASTOS DETALHADOS'!$F:$F,J35) -> 0
B36: =SUM(B34) -> 0 | E36: =SUM(E34) -> 0 | H36: =SUM(H34) -> 0 | K36: =SUM(K34) -> 0
A37: SISTEMA GESTÃO E VENDAS | D37: SISTEMA GESTÃO E VENDAS | E37: =SUMIFS('GASTOS DETALHADOS'!$C:$C,'GASTOS DETALHADOS'!$E:$E,D$1,'GASTOS DETALHADOS'!$F:$F,D37) -> 0 | G37: SISTEMA GESTÃO E VENDAS | H37: =SUMIFS('GASTOS DETALHADOS'!$C:$C,'GASTOS DETALHADOS'!$E:$E,G$1,'GASTOS DETALHADOS'!$F:$F,G37) -> 0 | J37: SISTEMA GESTÃO E VENDAS | K37: =SUMIFS('GASTOS DETALHADOS'!$C:$C,'GASTOS DETALHADOS'!$E:$E,J$1,'GASTOS DETALHADOS'!$F:$F,J37) -> 0
A38: SISTEMA | B38: =SUMIFS('GASTOS DETALHADOS'!$C:$C,'GASTOS DETALHADOS'!$E:$E,A$1,'GASTOS DETALHADOS'!$F:$F,A38) -> 0 | D38: SISTEMA | E38: =SUMIFS('GASTOS DETALHADOS'!$C:$C,'GASTOS DETALHADOS'!$E:$E,D$1,'GASTOS DETALHADOS'!$F:$F,D38) -> 52.8 | G38: SISTEMA | H38: =SUMIFS('GASTOS DETALHADOS'!$C:$C,'GASTOS DETALHADOS'!$E:$E,G$1,'GASTOS DETALHADOS'!$F:$F,G38) -> 47.8 | J38: SISTEMA | K38: =SUMIFS('GASTOS DETALHADOS'!$C:$C,'GASTOS DETALHADOS'!$E:$E,J$1,'GASTOS DETALHADOS'!$F:$F,J38) -> 0
B39: =B38 -> 0 | E39: =E38 -> 52.8 | H39: =H38 -> 47.8 | K39: =K38 -> 0
A40: MUSICOS | D40: MUSICOS | E40: =SUMIFS('GASTOS DETALHADOS'!$C:$C,'GASTOS DETALHADOS'!$E:$E,D$1,'GASTOS DETALHADOS'!$F:$F,D40) -> 0 | G40: MUSICOS | H40: =SUMIFS('GASTOS DETALHADOS'!$C:$C,'GASTOS DETALHADOS'!$E:$E,G$1,'GASTOS DETALHADOS'!$F:$F,G40) -> 0 | J40: MUSICOS | K40: =SUMIFS('GASTOS DETALHADOS'!$C:$C,'GASTOS DETALHADOS'!$E:$E,J$1,'GASTOS DETALHADOS'!$F:$F,J40) -> 0
...

Sheet GASTOS DETALHADOS
A1: PI | B1: Dt. Pagto | C1: Vlr. Pagto | D1: Fornecedor | E1: ESPAÇO | F1: SETOR | G1: NF
A2: 178 | B2: 46143 | C2: 210 | D2: GREGORY GASPAR DE F. PROAK | E2: L1 | F2: SEGURANÇA | G2: 106
A3: 178 | B3: 46143 | C3: 100 | D3: Jordana Gabriela do Sanros Carvalho | E3: L1 | F3: STAFF FAXINA/MONTAGEM | G3: 107
A4: 176 | B4: 46147 | C4: 380 | D4: RAMALHETE DE MIRRA LOCACOES | E4: YOU | F4: ALUGUEL ITENS DIVERSOS | G4: 04052026
A5: 176 | B5: 46162 | C5: 1950 | D5: RAMALHETE DE MIRRA LOCACOES | E5: YOU | F5: ALUGUEL ITENS DIVERSOS | G5: 19052026
A6: 176 | B6: 46148 | C6: 585 | D6: VIP Service Personal Locação e Festas Ltda | E6: YOU | F6: ALUGUEL ITENS DIVERSOS | G6: 05052026
A7: 176 | B7: 46151 | C7: 42 | D7: VIP Service Personal Locação e Festas Ltda | E7: YOU | F7: ALUGUEL ITENS DIVERSOS | G7: reposicao coposalugados
A8: 176 | B8: 46151 | C8: 42 | D8: VIP Service Personal Locação e Festas Ltda | E8: YOU | F8: ALUGUEL ITENS DIVERSOS | G8: reposicao coposalugados
A9: 176 | B9: 46160 | C9: 370 | D9: VIP Service Personal Locação e Festas Ltda | E9: YOU | F9: ALUGUEL ITENS DIVERSOS | G9: 1805
A10: 176 | B10: 46160 | C10: 175.26 | D10: COPEL DISTRIBUICAO S/A | E10: YOU | F10: CUSTOS BÁSICOS | G10: 06052026146982
A11: 176 | B11: 46168 | C11: 113.27 | D11: Governo Federal / Imp. Ret. Forn / INSS | E11: YOU | F11: IMPOSTOS | G11: 2605
A12: 176 | B12: 46168 | C12: 113.27 | D12: Governo Federal / Imp. Ret. Forn / IR | E12: YOU | F12: IMPOSTOS | G12: 2605
A13: 176 | B13: 46149 | C13: 3341.64 | D13: Governo Federal / Imp. Ret. Forn / PIS-Coﬁns-CSLL | E13: YOU | F13: IMPOSTOS | G13: simples nacional
A14: 176 | B14: 46149 | C14: 9679.96 | D14: Governo Federal / Imp. Ret. Forn / PIS-Coﬁns-CSLL | E14: YOU | F14: IMPOSTOS | G14: simples nacional 2
A15: 176 | B15: 46168 | C15: 113.27 | D15: Governo Federal / Imp. Ret. Forn / PIS-Coﬁns-CSLL | E15: YOU | F15: IMPOSTOS | G15: 2605
... A34: 178 | B34: 46146 | C34: 19.4 | D34: 99 POP | E34: YOU | F34: TRANSPORTE | G34: manutencao maquina de
A35: 178 | B35: 46146 | C35: 120 | D35: ADRIEL DE OLIVEIRA FERNANDES | E35: L2 | F35: STAFF FAXINA/MONTAGEM | G35: 416
A36: 176 | B36: 46143 | C36: 2000 | D36: AÇOUGUE TIROLEZA | E36: YOU | F36: INSUMO COZ | G36: carnes 01 e 02
A37: 176 | B37: 46144 | C37: 69.86 | D37: AÇOUGUE TIROLEZA | E37: YOU | F37: INSUMO COZ | G37: carn3s 02/05
A38: 178 | B38: 46146 | C38: 109.4 | D38: EBAZAR.COM.BR LTDA | E38: L1 | F38: MANUTENÇÃO | G38: refil etiqueta
A39: 176 | B39: 46144 | C39: 225.41 | D39: AÇOUGUE TIROLEZA | E39: YOU | F39: INSUMO COZ | G39: estrogonoff staffcontratado
A40: 178 | B40: 46146 | C40: 1340 | D40: MADERA LOCACAO DE MOVEIS | E40: L1 | F40: ALUGUEL ITENS DIVERSOS | G40: 405
A41: 178 | B41: 46146 | C41: 195 | D41: Xin Eletronicos | E41: L1 | F41: MANUTENÇÃO | G41: 405
A42: 176 | B42: 46149 | C42: 1595.2 | D42: AÇOUGUE TIROLEZA | E42: YOU | F42: INSUMO COZ | G42: moida empanada,frango teriakymusculo ragu
A43: 176 | B43: 46154 | C43: 1112.15 | D43: AÇOUGUE TIROLEZA | E43: YOU | F43: INSUMO COZ | G43: eventos 08 e 09mini burguer,borghignon,mignon e
A44: 176 | B44: 46156 | C44: 252.92 | D44: AÇOUGUE TIROLEZA | E44: YOU | F44: INSUMO COZ | G44: mini burguer eteriaky
A45: 176 | B45: 46157 | C45: 179.74 | D45: AÇOUGUE TIROLEZA | E45: YOU | F45: INSUMO COZ | G45: musculobourghignon
A46: 176 | B46: 46163 | C46: 673.67 | D46: AÇOUGUE TIROLEZA | E46: YOU | F46: INSUMO COZ | G46: teriaky e ragu
A47: 176 | B47: 46170 | C47: 232.91 | D47: AÇOUGUE TIROLEZA | E47: YOU | F47: INSUMO COZ | G47: teriaky estrogonoff pacotestaff
A48: 176 | B48: 46147 | C48: 49.8 | D48: ARMAZEM DAS EMBALAGENS | E48: YOU | F48: INSUMO COZ | G48: caixinhas
A49: 176 | B49: 46151 | C49: 9.2 | D49: ARMAZEM DAS EMBALAGENS | E49: YOU | F49: INSUMO COZ | G49: embalagenshotdog
A50: 176 | B50: 46162 | C50: 53.6 | D50: ARMAZEM DAS EMBALAGENS | E50: YOU | F50: INSUMO COZ | G50: csixinhas
A51: 176 | B51: 46164 | C51: 78 | D51: ARMAZEM DAS EMBALAGENS | E51: YOU | F51: INSUMO COZ | G51: embalagempizzas
A52: 176 | B52: 46171 | C52: 52 | D52: ARMAZEM DAS EMBALAGENS | E52: YOU | F52: INSUMO COZ | G52: embalagens pizza
A53: 176 | B53: 46159 | C53: 26.16 | D53: Atacadao S A | E53: YOU | F53: INSUMO COZ | G53: aipim
... A69: 176 | B69: 46156 | C69: 82.03 | D69: CONDOR SUPER CENTER LTDA | E69: YOU | F69: INSUMO COZ | G69: bruschetta ecsene de onça
A70: 178 | B70: 46148 | C70: 145.5 | D70: Emily Carolini Gomes Ribeiro | E70: L1 | F70: STAFF ESPAÇO | G70: 608
A71: 178 | B71: 46148 | C71: 220 | D71: GREGORY GASPAR DE F. PROAK | E71: L1 | F71: SEGURANÇA | G71: 610
A72: 178 | B72: 46148 | C72: 210 | D72: GREGORY GASPAR DE F. PROAK | E72: L1 | F72: SEGURANÇA | G72: 611
A73: 178 | B73: 46148 | C73: 210 | D73: GREGORY GASPAR DE F. PROAK | E73: L1 | F73: SEGURANÇA | G73: 612
...

Sheet Cópia de GASTOS DETALHADOS
A1: PI | B1: Dt. Pagto | C1: Vlr. Pagto | D1: Fornecedor | E1: ESPAÇO | F1: SETOR | G1: NF
A2: 176 | B2: 46203 | C2: 437.74 | D2: SENDAS DISTRIBUIDORA S/A | E2: YOU | G2: degustação
A3: 176 | B3: 46203 | C3: 21.98 | D3: SACOLAO POPULAR CURITIBANO | G3: moiashi e manjericao
A4: 176 | B4: 46203 | C4: 406.11 | D4: CAMILO E TUTUMI HORTIFRUTI | G4: eventos
A5: 176 | B5: 46203 | C5: 51.22 | D5: EBAZAR.COM.BR LTDA | G5: utensilio coz
A6: 176 | B6: 46203 | C6: 1048.69 | D6: Aurora Cooperativa | G6: parmesao e manteiga
A7: 176 | B7: 46203 | C7: 72.19 | D7: SENDAS DISTRIBUIDORA S/A | G7: 1
A8: 176 | B8: 46203 | C8: 136 | D8: Thaissa cubas ribeiro dos santos | G8: 3007
A9: 176 | B9: 46203 | C9: 136 | D9: alyne carolina ropelato pacheco | G9: 3008
A10: 176 | B10: 46203 | C10: 136 | D10: Paula Kimberlly Martins Petrin | G10: 3009
A11: 176 | B11: 46203 | C11: 153 | D11: leandro lima | G11: 3009
A12: 176 | B12: 46203 | C12: 153 | D12: Hidaryane nogueira bento | G12: 3010
A13: 176 | B13: 46203 | C13: 150 | D13: Eudes Jhunior silva | G13: 300620261
A14: 176 | B14: 46202 | C14: 255 | D14: Alexis santos de Almeida | G14: taxa cozinha 27
A15: 176 | B15: 46202 | C15: 255 | D15: tathiane borcathe | G15: taxa cozinha 27
A16: 176 | B16: 46202 | C16: 160 | D16: Sônia de Jesus | G16: taxa cozinha sobremesas
A17: 176 | B17: 46202 | C17: 840 | D17: Daniel Bueno Bettega | G17: 1102
A18: 176 | B18: 46202 | C18: 1190 | D18: Eric Chien | G18: 2706
A19: 176 | B19: 46202 | C19: 2692.3 | D19: Google Inc | G19: ads20260601
A20: 176 | B20: 46202 | C20: 167.82 | D20: SENDAS DISTRIBUIDORA S/A | G20: evento 30/06
A21: 176 | B21: 46201 | C21: 247 | D21: carlos alexandre almeida de souza | G21: 2801
A22: 176 | B22: 46201 | C22: 161.5 | D22: Luiz Fernando de Jesus Rosa | G22: 280620261
A23: 176 | B23: 46201 | C23: 166.24 | D23: ZE DELIVERY APP | G23: ze dwli
A24: 176 | B24: 46201 | C24: 161.5 | D24: Fernanda Cristina Yamawaki | G24: 280620262
A25: 176 | B25: 46201 | C25: 161.5 | D25: gustavo pereira da silva | G25: 280620263
A26: 176 | B26: 46201 | C26: 161.5 | D26: luciane vieira dos santos | G26: 280620264
A27: 176 | B27: 46201 | C27: 178.5 | D27: aluir henrique | G27: 280620265
A28: 176 | B28: 46201 | C28: 178.5 | D28: Victor Sabino camargo | G28: 280620267
A29: 176 | B29: 46201 | C29: 178.5 | D29: ADRIEL DE OLIVEIRA FERNANDES | G29: 28062026
A30: 176 | B30: 46201 | C30: 153 | D30: NAIARA THAIS TOALDO PINHEIRO | G30: 2806202610
A31: 176 | B31: 46201 | C31: 161.5 | D31: Heictor Bellato Araujo | G31: 2806202611
A32: 176 | B32: 46201 | C32: 150 | D32: eduardo monteiro pinto | G32: 2806202613
A33: 176 | B33: 46201 | C33: 275 | D33: Vanessa Andreina | G33: 2806202630
A34: 176 | B34: 46201 | C34: 178 | D34: Eliana da silva moura | G34: louca cozinha
A35: 176 | B35: 46201 | C35: 178.5 | D35: Larissa Araujo | G35: 28062026
A36: 176 | B36: 46200 | C36: 153 | D36: Frederick Augusto Cezar Santos | G36: 2706
A37: 176 | B37: 46200 | C37: 153 | D37: DIOGO LUIZ ARAUJO | G37: 2702
A38: 176 | B38: 46200 | C38: 153 | D38: joel duarte | G38: 2703
A39: 176 | B39: 46200 | C39: 153 | D39: Andre Felipe Sartorelli | G39: 2705
A40: 176 | B40: 46200 | C40: 153 | D40: leandro lima | G40: 2707
...
